Workbook

Sheet Policy Portal
A1: Sr. No. | B1: Registration No. | C1: Registration Date | D1: MAKE/MODEL | E1: From | F1: To | G1: Model | H1: Size | I1: Owner | J1: From | K1: To | L1: Insurance Company | M1: Policy No | N1: GVW | O1: IDV | P1: Premium Amount | Q1: Remarks | R1: NCB | S1: PREMIUM | V1: This year idv | W1: NEW IDV | X1: NCB | Y1: RSD TAKEN | Z1: IMT 23 | AA1: zero dep+ Towing cover 20000 | AB1: PREMIUM QUOTE | AC1: RENEWED | AD1: NEW EXPIRY DT | AE1: RENEWED DT
A2: 1 | B2: GJ-18-BW-1144 | C2: 45649 | E2: {=VLOOKUP($B$2:$B$35,[1]Sheet1!B$2:H$35,6,0)} -> 45545 | F2: {=VLOOKUP($B$2:$B$35,[1]Sheet1!B$2:H$35,7,0)} -> 45909 | G2: TIPPER | H2: 20 FT | I2: SR CONTAINER CARRIERS | J2: 45545 | K2: 45909 | L2: SBI general Insurance | M2: 0000000040753483/P031009241805042 | N2: 39500 | O2: 3530000 | P2: 89854 | R2: 0 | T2: 0.05 | U2: =O2*T2 -> 176500 | V2: =O2-U2 -> 3353500 | X2: 20 | Y2: 45940 | Z2: YES | AA2: YES | AB2: 74502
A3: 2 | B3: GJ-18-BV-5224 | C3: 45182 | E3: 45512 | F3: 45876 | G3: TIPPER | H3: 20 FT | I3: SR CONTAINER CARRIERS | J3: 45512 | K3: 45876 | L3: SBI general Insurance | M3: P030608241738266 | N3: 39500 | O3: 3600000 | P3: 56960 | R3: 20 | T3: 0.05 | U3: =O3*T3 -> 180000 | V3: =O3-U3 -> 3420000 | X3: 25 | Y3: 45940 | Z3: YES | AA3: NO | AB3: 53089
A4: 3 | B4: GJ-18-BV-5428 | C4: 45182 | E4: 45877 | F4: 46241 | G4: TIPPER | H4: 20 FT | I4: SR CONTAINER CARRIERS | J4: 45877 | K4: 46241 | L4: SBI general Insurance | M4: POCMVGC0100426831 | N4: 39500 | O4: 3006000 | P4: 55430 | R4: 25 | T4: 0.05 | U4: =O4*T4 -> 150300 | V4: =O4-U4 -> 2855700 | X4: 35 | Y4: 45940 | Z4: YES | AA4: NO | AB4: 51311
A5: 4 | B5: GJ-16-AU-5412 | C5: 43264 | E5: 45682 | F5: 46046 | J5: 45682 | K5: 46046 | L5: SHRIRAM GENERAL INSURANCE COMPANY LIMITED Generali Central Insurance Company Limited | M5: 10003/31/25/587624 | N5: 35000 | O5: 1212502 | P5: 70895 | R5: 0 | T5: 0.05 | U5: =O5*T5 -> 60625.1 | V5: =O5-U5 -> 1151876.9 | W5: 1140000 | X5: 20 | Y5: 45940 | Z5: YES | AA5: NO | AB5: 49500 | AC5: 50169 | AD5: 46411 | AE5: 46045
A6: 5 | B6: GJ-18-AZ-5588 | C6: 43157 | E6: 45695 | F6: 46059 | G6: TIPPER CNG | H6: 20 FT | I6: SR CONTAINER CARRIERS | J6: 45695 | K6: 46059 | L6: SHRIRAM GENERAL INSURANCE COMPANY LIMITED | M6: 213001/31/25/037244 | N6: 39500 | O6: 2400000 | P6: 54537 | R6: 0 | T6: 0.05 | U6: =O6*T6 -> 120000 | V6: =O6-U6 -> 2280000 | W6: 2410000 | X6: 20 | Y6: 45940 | Z6: YES | AA6: NO | AB6: 51387 | AC6: 51198 | AD6: 46424 | AE6: 46059
A7: 6 | B7: GJ-18-AZ-4495 | C7: 42921 | E7: 45848 | F7: 46212 | G7: BOLERO | I7: SR CONTAINER CARRIERS | J7: 45848 | K7: 46212 | L7: FUTURE GENERALI | M7: 132/02/17/0726/MTP/1010119267 | N7: 3225 | O7: 340000 | P7: 18490 | R7: 50 | T7: 0.05 | U7: =O7*T7 -> 17000 | V7: =O7-U7 -> 323000 | X7: 50 | Y7: 45940 | Z7: YES | AA7: NO | AB7: 17371
A8: 7 | B8: GJ-18-BV-8816 | C8: 42646 | E8: 45794 | F8: 46158 | G8: TIPPER | H8: 40 FT | I8: SR CONTAINER CARRIERS | J8: 45794 | K8: 46158 | L8: SHRIRAM GENERAL INSURANCE COMPANY LIMITED | M8: 213001/31/26/003188 | N8: 45500 | O8: 1500000 | P8: 54764 | R8: 0 | T8: 0.05 | U8: =O8*T8 -> 75000 | V8: =O8-U8 -> 1425000 | W8: 1510000 | X8: 20 | Y8: 45940 | Z8: YES | AA8: NO | AB8: 50386 | AC8: 51998 | AD8: 46523 | AE8: 46520
A9: 8 | B9: GJ-08-AW-8599 | C9: 42584 | E9: 45492 | F9: 45856 | G9: TRAILER | H9: 40 FT | I9: SR CONTAINER CARRIERS | J9: 19.07.2024 | K9: 18.07.2025 | L9: SHRIRAM GENERAL INSURANCE COMPANY LIMITED | M9: 10003/31/25/214280 | N9: 45500 | O9: 1425000 | P9: 87951 | T9: 0.05 | U9: =O9*T9 -> 71250 | V9: =O9-U9 -> 1353750 | Y9: 45940 | Z9: YES | AA9: NO | AB9: 0
A10: 9 | B10: GJ-12-BT-7142 | C10: 42527 | E10: 45772 | F10: 46136 | G10: TRAILER | H10: 40 FT | I10: SR CONTAINER CARRIERS | J10: 45772 | K10: 46136 | L10: SBI general Insurance | M10: POCMVGC0100329389 | N10: 45500 | O10: 2089500 | P10: 44342 | R10: 0 | T10: 0.05 | U10: =O10*T10 -> 104475 | V10: =O10-U10 -> 1985025 | W10: 1740000 | X10: 20 | Y10: 45940 | Z10: YES | AA10: NO | AB10: 51540 | AC10: 51408 | AD10: 46501 | AE10: 46135
A11: 10 | B11: GJ-18-AZ-0849 | C11: 42500 | E11: 45741 | F11: 46105 | G11: TIPPER | H11: 20 FT | I11: Suraj A Rajan (Proprietor) | J11: 45741 | K11: 46105 | L11: ROYAL SUNADRAM INSURANCE | M11: VGC1322471000100 | N11: 39500 | O11: 1440000 | P11: 57169 | R11: 25 | T11: 0.05 | U11: =O11*T11 -> 72000 | V11: =O11-U11 -> 1368000 | W11: 1368000 | X11: 35 | Y11: 45940 | Z11: YES | AA11: NO | AB11: 50182 | AC11: 53867 | AD11: 46470 | AE11: 46104
A12: 11 | B12: GJ-18-AX-6955 | C12: 42185 | E12: 45817 | F12: 46181 | G12: TIPPER | H12: 20 FT | I12: Suraj A Rajan (Proprietor) | J12: 45817 | K12: 46181 | L12: SHRIRAM GENERAL INSURANCE COMPANY LIMITED | M12: 213001/31/26/004903 | N12: 39500 | O12: 1100000 | P12: 52147 | R12: 0 | T12: 0.05 | U12: =O12*T12 -> 55000 | V12: =O12-U12 -> 1045000 | X12: 20 | Y12: 45940 | Z12: YES | AA12: NO | AB12: 50174
A13: 12 | B13: GJ-18-AZ-4229 | C13: 41446 | E13: 45745 | F13: 46109 | G13: TRAILER | H13: 40 FT | I13: Suraj A Rajan (Proprietor) | J13: 45745 | K13: 46109 | L13: SBI general Insurance | M13: 38006811 | N13: 45500 | O13: 900000 | P13: 52547 | R13: 0 | T13: 0.05 | U13: =O13*T13 -> 45000 | V13: =O13-U13 -> 855000 | W13: 900000 | X13: 20 | Y13: 45940 | Z13: YES | AA13: NO | AB13: 49520 | AC13: 48540 | AD13: 46474 | AE13: 46106
A14: 13 | B14: GJ-18-AV-7468 | C14: 41443 | E14: 45810 | F14: 46174 | G14: TIPPER | H14: 40 FT | I14: Suraj A Rajan (Proprietor) | J14: 45810 | K14: 46174 | L14: SHRIRAM GENERAL INSURANCE COMPANY LIMITED | M14: 213001/31/26/004506 | N14: 45500 | O14: 1100000 | P14: 51792 | R14: 0 | T14: 0.05 | U14: =O14*T14 -> 55000 | V14: =O14-U14 -> 1045000 | W14: 1050000 | X14: 20 | Y14: 45940 | Z14: YES | AA14: NO | AB14: 49900 | AC14: 51588 | AD14: 46539 | AE14: 46174
A15: 14 | B15: GJ-18-BV-6050 | C15: 41166 | E15: 45583 | F15: 45947 | G15: TRAILER | H15: 20 FT | I15: SR CONTAINER CARRIERS | J15: 45583 | K15: 45947 | L15: MAGMA HDI | M15: P0025200007/4103/103112 | N15: 39500 | O15: 892000 | P15: 51920 | R15: 20 | T15: 0.05 | U15: =O15*T15 -> 44600 | V15: =O15-U15 -> 847400 | X15: 25 | Y15: 45940 | Z15: YES | AA15: NO | AB15: 48900
A16: 15 | B16: GJ-18-BV-9156 | C16: 41156 | E16: 45776 | F16: 46140 | G16: TIPPER | H16: 20 FT | I16: SR CONTAINER CARRIERS | J16: 45776 | K16: 46140 | L16: ROYAL SUNADRAM INSURANCE | M16: VGC1335520000100 | N16: 39500 | O16: 1080257 | P16: 52294 | R16: 20 | T16: 0.05 | U16: =O16*T16 -> 54012.85 | V16: =O16-U16 -> 1026244.2 | W16: 1080000 | X16: 25 | Y16: 45940 | Z16: YES | AA16: NO | AB16: 48873 | AC16: 49387 | AD16: 46505 | AE16: 46137
A17: 16 | B17: GJ-18-BT-5220 | C17: 40988 | E17: 45642 | F17: 46006 | G17: TIPPER | H17: 20 FT | I17: Suraj A Rajan (Proprietor) | J17: 45642 | K17: 46006 | L17: SHRIRAM GENERAL INSURANCE COMPANY LIMITED | M17: 213001/31/25/032050 | N17: 39500 | O17: 810000 | P17: 51363 | R17: 0 | T17: 0.05 | U17: =O17*T17 -> 40500 | V17: =O17-U17 -> 769500 | W17: 760000 | X17: 20 | Y17: 45940 | Z17: YES | AA17: NO | AB17: 48798 | AC17: 48808 | AD17: 46371 | AE17: 46002
A18: 17 | B18: GJ-09-Z-4266 | C18: 40966 | E18: 45763 | F18: 46127 | G18: 12 WHEEL | H18: 20 FT | I18: SR CONTAINER CARRIERS | J18: 45763 | K18: 46127 | L18: SHRIRAM GENERAL INSURANCE COMPANY LIMITED | M18: 213001/31/26/000989 | N18: 35000 | O18: 1200000 | P18: 52246 | R18: 0 | T18: 0.05 | U18: =O18*T18 -> 60000 | V18: 1150000 | W18: 1115000 | X18: 20 | Y18: 45940 | Z18: YES | AA18: NO | AB18: 49200 | AC18: 48902 | AD18: 46492 | AE18: 46127
A19: 18 | B19: GJ-01-CX-2097 | C19: 40821 | E19: 45562 | F19: 45926 | G19: TRAILER | H19: 40 FT | I19: SR CONTAINER CARRIERS | J19: 45562 | K19: 45926 | L19: SBI general Insurance | M19: P032509241835493 | N19: 45500 | O19: 1100000 | P19: 55568 | R19: 0 | T19: 0.05 | U19: =O19*T19 -> 55000 | V19: =O19-U19 -> 1045000 | X19: 20 | Y19: 45940 | Z19: YES | AA19: NO | AB19: 49900
A20: 19 | B20: GJ-18-AU-8480 | C20: 40819 | E20: 45668 | F20: 46032 | G20: 12 WHEEL | H20: 20 FT | I20: SR CONTAINER CARRIERS | J20: 45668 | K20: 46032 | L20: SHRIRAM GENERAL INSURANCE COMPANY LIMITED | M20: 213001/31/25/034557 | N20: 35000 | O20: 1080000 | P20: 52222 | R20: 0 | T20: 0.05 | U20: =O20*T20 -> 54000 | V20: =O20-U20 -> 1026000 | W20: 1070000 | X20: 20 | Y20: 45940 | Z20: YES | AA20: NO | AB20: 49133 | AC20: 49245 | AD20: 46397 | AE20: 46031
A21: 20 | B21: GJ-01-CV-4935 | C21: 40718 | E21: 45503 | F21: 45867 | G21: TAURUS | H21: 20 FT | I21: SR CONTAINER CARRIERS | J21: 45503 | K21: 45867 | L21: Go Digit General Insurance Ltd | M21: D157747087/29072024 | N21: 28000 | O21: 470000 | P21: 50575 | R21: 50 | T21: 0.05 | U21: =O21*T21 -> 23500 | V21: =O21-U21 -> 446500 | X21: 50 | Y21: 45940 | Z21: YES | AA21: NO | AB21: 47323
A22: 21 | B22: GJ-18-AZ-5394 | C22: 40376 | E22: 45660 | F22: 46024 | G22: TRAILER | H22: 20 FT | I22: Suraj A Rajan (Proprietor) | J22: 45660 | K22: 46024 | L22: MEGMA GENERAL INSURANCE LIMITED | M22: P0025200007/4103/104588 | N22: 39500 | O22: 800000 | P22: 51370 | R22: 50 | T22: 0.05 | U22: =O22*T22 -> 40000 | V22: =O22-U22 -> 760000 | W22: 790000 | X22: 50 | Y22: 45940 | Z22: YES | AA22: NO | AB22: 48028 | AC22: 48045 | AD22: 46389 | AE22: 46022
A23: 22 | B23: GJ-20-U-7188 | C23: 40312 | E23: 45585 | F23: 45949 | G23: TAURUS | H23: 20 FT | I23: Suraj A Rajan (Proprietor) | J23: 45585 | K23: 45949 | L23: SBI general Insurance | M23: P031810241880544 | N23: 28000 | O23: 819775 | P23: 51944 | R23: 50 | T23: 0.05 | U23: =O23*T23 -> 40988.75 | V23: =O23-U23 -> 778786.25 | X23: 50 | Y23: 45940 | Z23: YES | AA23: NO | AB23: 47978
A24: 23 | B24: GJ-12-Z-3234 | C24: 39784 | E24: 45648 | F24: 46012 | G24: TRAILER | H24: 20 FT | I24: SR CONTAINER CARRIERS | J24: 45648 | K24: 46012 | L24: Go Digit General Insurance Ltd | M24: D179043211 / 21122024 | N24: 39500 | O24: 900000 | P24: 52965 | R24: 25 | T24: 0.05 | U24: =O24*T24 -> 45000 | V24: =O24-U24 -> 855000 | W24: 895000 | X24: 35 | Y24: 45940 | Z24: YES | AA24: NO | AB24: 48346 | AC24: 48505 | AD24: 46377 | AE24: 46010
A25: 24 | B25: GJ-12-Z-2989 | C25: 39716 | E25: 45712 | F25: 46076 | G25: TRAILER | H25: 20 FT | I25: SR CONTAINER CARRIERS | J25: 45712 | K25: 46076 | L25: SHRIRAM GENERAL INSURANCE COMPANY LIMITED | M25: 213001/31/25/038511 | N25: 39500 | O25: 487000 | P25: 51165 | R25: 0 | T25: 0.05 | U25: =O25*T25 -> 24350 | V25: =O25-U25 -> 462650 | W25: 497000 | X25: 20 | Y25: 45940 | Z25: YES | AA25: NO | AB25: 48313 | AC25: 48274 | AD25: 46441 | AE25: 46074
A26: 25 | B26: GJ-18-AX-0063 | C26: 39714 | E26: 45648 | F26: 46012 | G26: TIPPER | H26: 20 FT | I26: Suraj A Rajan (Proprietor) | J26: 45648 | K26: 46012 | L26: SHRIRAM GENERAL INSURANCE COMPANY LIMITED | M26: 213001/31/25/032488 | N26: 39500 | O26: 810000 | P26: 50911 | R26: 0 | T26: 0.05 | U26: =O26*T26 -> 40500 | V26: =O26-U26 -> 769500 | W26: 800000 | X26: 20 | Y26: 45940 | Z26: YES | AA26: NO | AB26: 48910 | AC26: 48058 | AD26: 46377 | AE26: 46010
A27: 26 | B27: GJ-18-AX-6284 | C27: 39638 | E27: 45496 | F27: 45860 | G27: TRAILER | H27: 40 FT | I27: Suraj A Rajan (Proprietor) | J27: 45496 | K27: 45860 | L27: SBI general Insurance | M27: P032007241706097 | N27: 45500 | O27: 700000 | P27: 52372 | R27: 35 | T27: 0.05 | U27: =O27*T27 -> 35000 | V27: =O27-U27 -> 665000 | X27: 45 | Y27: 45940 | Z27: YES | AA27: NO | AB27: 48900
A28: 27 | B28: GJ-12-Z-1317 | C28: 39444 | E28: 45693 | F28: 46057 | G28: TRAILER | H28: 20 FT | I28: Suraj A Rajan (Proprietor) | J28: 45693 | K28: 46057 | L28: SHRIRAM GENERAL INSURANCE COMPANY LIMITED | M28: 213001/31/25/036980 | N28: 39500 | O28: 530000 | P28: 50671 | R28: 0 | T28: 0.05 | U28: =O28*T28 -> 26500 | V28: =O28-U28 -> 503500 | W28: 520000 | X28: 20 | Y28: 45940 | Z28: YES | AA28: NO | AB28: 48386 | AC28: 47645 | AD28: 46422 | AE28: 46055
A29: 28 | B29: GJ-12-Z-1089 | C29: 39413 | E29: 45742 | F29: 46106 | G29: TRAILER | H29: 20 FT | I29: SR CONTAINER CARRIERS | J29: 45742 | K29: 46106 | L29: SHRIRAM GENERAL INSURANCE COMPANY LIMITED | M29: 213001/31/25/040767 | N29: 39500 | O29: 440000 | P29: 50968 | R29: 0 | T29: 0.05 | U29: =O29*T29 -> 22000 | V29: 462650 | W29: 466000 | X29: 20 | Y29: 45940 | Z29: YES | AA29: NO | AB29: 48313 | AC29: 47965 | AD29: 46471 | AE29: 46104
A30: 29 | B30: GJ-12-Z-1090 | C30: 39413 | E30: 45747 | F30: 46111 | G30: TRAILER | H30: 40 FT | I30: SR CONTAINER CARRIERS | J30: 45747 | K30: 46111 | L30: Go Digit General Insurance Ltd | M30: D181071478 / 28032025 | N30: 39500 | O30: 455000 | P30: 50724 | R30: 35 | T30: 0.05 | U30: =O30*T30 -> 22750 | V30: =O30-U30 -> 432250 | W30: 466000 | X30: 45 | Y30: 45940 | Z30: YES | AA30: NO | AB30: 47775 | AC30: 47710 | AD30: 46476 | AE30: 46107
A31: 30 | B31: GJ-18-AV-8971 | C31: 38874 | E31: 45629 | F31: 45993 | G31: TRAILER | H31: 40 FT | I31: Suraj A Rajan (Proprietor) | J31: 45629 | K31: 45993 | L31: Reliance General Insurance Company Limited | M31: 666222423340016000 | N31: 40200 | O31: 700000 | P31: 53395 | R31: 25 | T31: 0.05 | U31: =O31*T31 -> 35000 | V31: =O31-U31 -> 665000 | W31: 655000 | X31: 35 | Y31: 45940 | Z31: YES | AA31: NO | AB31: 48500 | AC31: 48621 | AD31: 46358 | AE31: 45990
A32: 31 | B32: GJ-01-AU-4504 | C32: 38651 | E32: 45621 | F32: 45985 | G32: TRAILER | H32: 20 FT | I32: SR CONTAINER CARRIERS | J32: 45621 | K32: 45985 | L32: Go Digit General Insurance Ltd. | M32: D175313243 / 23112024 | N32: 39500 | O32: 472532 | P32: 51141 | R32: 0 | T32: 0.05 | U32: =O32*T32 -> 23626.6 | V32: 462650 | W32: 462650 | X32: 20 | Y32: 45940 | Z32: YES | AA32: NO | AB32: 48313 | AC32: 48413 | AD32: 46350 | AE32: 45982
A33: 32 | B33: GJ-18-AV-4735 | C33: 38390 | E33: 45389 | F33: 45753 | G33: TAURUS | H33: 20 FT | I33: Suraj A Rajan (Proprietor) | J33: 45754 | K33: 46118 | L33: Go Digit General Insurance Ltd. | M33: D196440434 / 07042025 | N33: 28000 | O33: 342000 | P33: 50413 | R33: 50 | T33: 0.05 | U33: =O33*T33 -> 17100 | V33: =O33-U33 -> 324900 | W33: 342000 | X33: 50 | Y33: 45940 | Z33: YES | AA33: NO | AB33: 47035 | AC33: 47165 | AD33: 46483 | AE33: 46115
A34: 33 | B34: GJ-18-AV-4737 | C34: 38390 | E34: 45687 | F34: 46051 | G34: TAURUS | H34: 20 FT | I34: Suraj A Rajan (Proprietor) | J34: 45687 | K34: 46051 | L34: SHRIRAM GENERAL INSURANCE COMPANY LIMITED | M34: 213001/31/25/036191 | N34: 28000 | O34: 453739 | P34: 50252 | R34: 0 | T34: 0.05 | U34: =O34*T34 -> 22686.95 | V34: =O34-U34 -> 431052.05 | W34: 443739 | X34: 20 | Y34: 45940 | Z34: YES | AA34: NO | AB34: 47750 | AC34: 47994 | AD34: 46416 | AE34: 46049
A35: 34 | B35: GJ-15-X-8939 | C35: 38251 | E35: 45557 | F35: 45921 | G35: TAURUS | H35: 20 FT | I35: Suraj A Rajan (Proprietor) | J35: 45557 | K35: 45921 | L35: Tata AIG General Insurance Company LTD | M35: 6302124302 00 00 | N35: 25000 | O35: 630000 | P35: 49499 | R35: 45 | T35: 0.05 | U35: =O35*T35 -> 31500 | V35: =O35-U35 -> 598500 | X35: 50 | Y35: 45940 | Z35: YES | AA35: NO | AB35: 47298
A36: 35 | B36: GJ-18-BW-6133 | C36: 42390 | I36: SR CONTAINER CARRIERS | J36: 46041 | K36: 46405 | L36: UNIVERSAL SOMPO GENERAL INSURANCE COMPANY LIMITED | M36: USGAF231566575878 | N36: 45500 | W36: 1500000 | AC36: 51998 | AD36: 46405 | AE36: 46041
A37: 35 | B37: RJ-32-GB-4532 | C37: 42390 | I37: RAKESH GUruAR | J37: 45711 | K37: 46075 | L37: National Insurance Company Limited | M37: 351500312419038643 | N37: 45500 | O37: 1500000 | P37: 59631
A38: 36 | B38: GJ-12-BX-8779 | C38: 46296 | I38: NARAYANBHAI MANSUKHBHAI GADHAVI | J38: 45707 | K38: 46071 | L38: Reliance General Insurance Company Limited | M38: 666222523340004521 | N38: 45500 | O38: 1600000 | P38: 54240 | W38: 1600000
A39: 36 | B39: GJ-12-BX-8779 | C39: 46296 | J39: 46043 | K39: 46407 | L39: UNIVERSAL SOMPO GENERAL INSURANCE COMPANY LIMITED | M39: AVO/2315/20034797 | N39: 45500 | W39: 1600000 | AC39: 52207 | AD39: 46407 | AE39: 46043
A40: 37 | B40: GJ-18-BW-8733
...

Sheet F Data-NEW
A1: Sr No | B1: Renewal Date | C1: REGISTRATION NUMBER | D1: Policy No. | E1: Period of Insurance(From) | F1: Period of Insurance(To) | G1: ENGINE NUMBER | H1: CHASSIS NUMBER | I1: MAKE/MODEL | J1: CUBIC CAPACITY/KW/GVW | K1: MFG. YEAR / REGISTRATION DATE | L1: VEHICLE IDV | M1: ELECTRICAL ACCESSORIES IDV | N1: CNG KIT IDV | O1: TOTAL IDV (VALUE) | P1: OD PREMIUM | Q1: IMT23 | R1: IMT24 | S1: IMT25 | T1: No Claim Bonus | U1: TOTAL OD PREMIUM | V1: IMT17 | W1: IMT252 | X1: IMT28 | Y1: IMT29 | Z1: LIABILITY PREMIUM | AA1: TOTAL GST | AB1: TOTAL POLICY PREMIUM | AC1: REMARKS
A2: 1 | B2: 45982 | C2: GJ-01-AU-4504 | D2: AVO/2315/12455920 | E2: 45986 | F2: 46350 | G2: NDE414910 | H2: NDR138946 | I2: ASHOK LEYLAND 3516 H/ AL | J2: 5883 / 35200 | K2: 2005 / 26-10-2005 | L2: 462650 | M2: 12000 | N2: 0 | O2: =Table1[[#This Row],[VEHICLE IDV]]+Table1[[#This Row],[ELECTRICAL ACCESSORIES IDV]]+Table1[[#This Row],[CNG KIT IDV]] -> 474650 | P2: 1464 | Q2: 220 | R2: 480 | S2: 0 | T2: -433 | U2: =SUM(Table1[[#This Row],[OD PREMIUM]:[No Claim Bonus]]) -> 1731 | V2: 50 | W2: 0 | X2: 50 | Y2: 0 | Z2: 44050 | AA2: =SUM(Table1[[#This Row],[TOTAL OD PREMIUM]:[IMT29]])*18%+Table1[[#This Row],[LIABILITY PREMIUM]]*5% -> 2532.08 | AB2: =Table1[[#This Row],[TOTAL OD PREMIUM]]+Table1[[#This Row],[IMT17]]+Table1[[#This Row],[IMT252]]+Table1[[#This Row],[IMT28]]+Table1[[#This Row],[IMT29]]+Table1[[#This Row],[LIABILITY PREMIUM]]+Table1[[#This Row],[TOTAL GST]] -> 48413.08
A3: 2 | B3: 45993 | C3: GJ-18-AV-8971 | D3: AVO/2315/12489557 | E3: 45994 | F3: 46358 | G3: 60D62474649 | H3: 447205STZ209895 | I3: TATA MOTORS LPS 4018. | J3: 5883 / 40200 | K3: 2006 / 06-06-2006 | L3: 655000 | M3: 7000 | N3: 0 | O3: =Table1[[#This Row],[VEHICLE IDV]]+Table1[[#This Row],[ELECTRICAL ACCESSORIES IDV]]+Table1[[#This Row],[CNG KIT IDV]] -> 662000 | P3: 1960 | Q3: 294 | R3: 280 | S3: 0 | T3: -887 | U3: =SUM(Table1[[#This Row],[OD PREMIUM]:[No Claim Bonus]]) -> 1647 | V3: 50 | W3: 0 | X3: 50 | Y3: 0 | Z3: 44342 | AA3: =SUM(Table1[[#This Row],[TOTAL OD PREMIUM]:[IMT29]])*18%+Table1[[#This Row],[LIABILITY PREMIUM]]*5% -> 2531.56 | AB3: =Table1[[#This Row],[TOTAL OD PREMIUM]]+Table1[[#This Row],[IMT17]]+Table1[[#This Row],[IMT252]]+Table1[[#This Row],[IMT28]]+Table1[[#This Row],[IMT29]]+Table1[[#This Row],[LIABILITY PREMIUM]]+Table1[[#This Row],[TOTAL GST]] -> 48620.56
A4: 3 | B4: 46002 | C4: GJ-18-BT-5220 | D4: AVO/2315/12516605 | E4: 46007 | F4: 46371 | G4: B591803121B63234901 | H4: MAT503010C3B06810 | I4: TATA MOTORS LIMITED TATA LPS 3518 | J4: 5883 / 39500 | K4: 2012 / 20-03-2012 | L4: 760000 | M4: 6000 | N4: 0 | O4: =Table1[[#This Row],[VEHICLE IDV]]+Table1[[#This Row],[ELECTRICAL ACCESSORIES IDV]]+Table1[[#This Row],[CNG KIT IDV]] -> 766000 | P4: 2134 | Q4: 320 | R4: 240 | S4: 0 | T4: -539 | U4: =SUM(Table1[[#This Row],[OD PREMIUM]:[No Claim Bonus]]) -> 2155 | V4: 50 | W4: 0 | X4: 50 | Y4: 0 | Z4: 43950 | AA4: =SUM(Table1[[#This Row],[TOTAL OD PREMIUM]:[IMT29]])*18%+Table1[[#This Row],[LIABILITY PREMIUM]]*5% -> 2603.4 | AB4: =Table1[[#This Row],[TOTAL OD PREMIUM]]+Table1[[#This Row],[IMT17]]+Table1[[#This Row],[IMT252]]+Table1[[#This Row],[IMT28]]+Table1[[#This Row],[IMT29]]+Table1[[#This Row],[LIABILITY PREMIUM]]+Table1[[#This Row],[TOTAL GST]] -> 48808.4
A5: 4 | B5: 46010 | C5: GJ-12-Z-3234 | D5: AVO/2315/12539154 | E5: 46013 | F5: 46377 | G5: 80G62697822 | H5: 415206HRZ308763 | I5: TATA LPS3516 TC32 EX | J5: 5883 / 39500 | K5: 2008 / 02-12-2008 | L5: 895000 | M5: 5000 | N5: 0 | O5: =Table1[[#This Row],[VEHICLE IDV]]+Table1[[#This Row],[ELECTRICAL ACCESSORIES IDV]]+Table1[[#This Row],[CNG KIT IDV]] -> 900000 | P5: 2365 | Q5: 355 | R5: 200 | S5: 0 | T5: -1022 | U5: =SUM(Table1[[#This Row],[OD PREMIUM]:[No Claim Bonus]]) -> 1898 | V5: 50 | W5: 0 | X5: 50 | Y5: 0 | Z5: 43950 | AA5: =SUM(Table1[[#This Row],[TOTAL OD PREMIUM]:[IMT29]])*18%+Table1[[#This Row],[LIABILITY PREMIUM]]*5% -> 2557.14 | AB5: =Table1[[#This Row],[TOTAL OD PREMIUM]]+Table1[[#This Row],[IMT17]]+Table1[[#This Row],[IMT252]]+Table1[[#This Row],[IMT28]]+Table1[[#This Row],[IMT29]]+Table1[[#This Row],[LIABILITY PREMIUM]]+Table1[[#This Row],[TOTAL GST]] -> 48505.14
A6: 5 | B6: 46010 | C6: GJ-18-AX-0063 | D6: AVO/2315/12539167 | E6: 46013 | F6: 46377 | G6: 80E62677349 | H6: 415206ERZ305315 | I6: TATA LPS3516 TC32 EX | J6: 5883 / 39500 | K6: 2008 / 23-09-2008 | L6: 800000 | M6: 10000 | N6: 0 | O6: =Table1[[#This Row],[VEHICLE IDV]]+Table1[[#This Row],[ELECTRICAL ACCESSORIES IDV]]+Table1[[#This Row],[CNG KIT IDV]] -> 810000 | P6: 2207 | Q6: 331 | R6: 400 | S6: 0 | T6: -1469 | U6: =SUM(Table1[[#This Row],[OD PREMIUM]:[No Claim Bonus]]) -> 1469 | V6: 100 | W6: 0 | X6: 50 | Y6: 0 | Z6: 43950 | AA6: =SUM(Table1[[#This Row],[TOTAL OD PREMIUM]:[IMT29]])*18%+Table1[[#This Row],[LIABILITY PREMIUM]]*5% -> 2488.92 | AB6: =Table1[[#This Row],[TOTAL OD PREMIUM]]+Table1[[#This Row],[IMT17]]+Table1[[#This Row],[IMT252]]+Table1[[#This Row],[IMT28]]+Table1[[#This Row],[IMT29]]+Table1[[#This Row],[LIABILITY PREMIUM]]+Table1[[#This Row],[TOTAL GST]] -> 48057.92
A7: 6 | B7: 46022 | C7: GJ-18-AZ-5394 | D7: AVO/2315/12539154 | E7: 46025 | F7: 46389 | G7: 160HP01F62893348 | H7: MAT415206A2F15024 | I7: TATA MOTORS LIMITED TATA LPS 3516 | J7: 5883 / 39500 | K7: 2010 / 17-07-2010 | L7: 790000 | M7: 10000 | N7: 0 | O7: =Table1[[#This Row],[VEHICLE IDV]]+Table1[[#This Row],[ELECTRICAL ACCESSORIES IDV]]+Table1[[#This Row],[CNG KIT IDV]] -> 800000 | P7: 2189 | Q7: 328 | R7: 400 | S7: 0 | T7: -1459 | U7: =SUM(Table1[[#This Row],[OD PREMIUM]:[No Claim Bonus]]) -> 1458 | V7: 50 | W7: 0 | X7: 100 | Y7: 0 | Z7: 43950 | AA7: =SUM(Table1[[#This Row],[TOTAL OD PREMIUM]:[IMT29]])*18%+Table1[[#This Row],[LIABILITY PREMIUM]]*5% -> 2486.94 | AB7: =Table1[[#This Row],[TOTAL OD PREMIUM]]+Table1[[#This Row],[IMT17]]+Table1[[#This Row],[IMT252]]+Table1[[#This Row],[IMT28]]+Table1[[#This Row],[IMT29]]+Table1[[#This Row],[LIABILITY PREMIUM]]+Table1[[#This Row],[TOTAL GST]] -> 48044.94
A8: 7 | B8: 46031 | C8: GJ-18-AU-8480 | D8: AVO/2315/20019944 | E8: 46033 | F8: 46397 | G8: F63144219 | H8: B3F15201 | I8: TATA MOTORS LTD LPT3118TC BS2 COWL | J8: 5883 / 35000 | K8: 2011 / 03-10-2011 | L8: 1070000 | M8: 10000 | N8: 0 | O8: =Table1[[#This Row],[VEHICLE IDV]]+Table1[[#This Row],[ELECTRICAL ACCESSORIES IDV]]+Table1[[#This Row],[CNG KIT IDV]] -> 1080000 | P8: 2579 | Q8: 387 | R8: 400 | S8: 0 | T8: -841 | U8: =SUM(Table1[[#This Row],[OD PREMIUM]:[No Claim Bonus]]) -> 2525 | V8: 50 | W8: 0 | X8: 50 | Y8: 0 | Z8: 43950 | AA8: =SUM(Table1[[#This Row],[TOTAL OD PREMIUM]:[IMT29]])*18%+Table1[[#This Row],[LIABILITY PREMIUM]]*5% -> 2670 | AB8: =Table1[[#This Row],[TOTAL OD PREMIUM]]+Table1[[#This Row],[IMT17]]+Table1[[#This Row],[IMT252]]+Table1[[#This Row],[IMT28]]+Table1[[#This Row],[IMT29]]+Table1[[#This Row],[LIABILITY PREMIUM]]+Table1[[#This Row],[TOTAL GST]] -> 49245
A9: 8 | B9: 46041 | C9: GJ-18-BW-6133 | D9: AVO/2315/20032118 | E9: 46041 | F9: 46405 | G9: 51M84271296 | H9: MAT447224FAP14285 | I9: TATA MOTORS LPS 4018 TC BS3 | J9: 5883 / 45500 | K9: 2015 / 25-01-2016 | L9: 1500000 | M9: 10000 | N9: 0 | O9: =Table1[[#This Row],[VEHICLE IDV]]+Table1[[#This Row],[ELECTRICAL ACCESSORIES IDV]]+Table1[[#This Row],[CNG KIT IDV]] -> 1510000 | P9: 3650 | Q9: 548 | R9: 400 | S9: 0 | T9: 0 | U9: =SUM(Table1[[#This Row],[OD PREMIUM]:[No Claim Bonus]]) -> 4598 | V9: 50 | W9: 0 | X9: 50 | Y9: 0 | Z9: 44242 | AA9: =SUM(Table1[[#This Row],[TOTAL OD PREMIUM]:[IMT29]])*18%+Table1[[#This Row],[LIABILITY PREMIUM]]*5% -> 3057.74 | AB9: =Table1[[#This Row],[TOTAL OD PREMIUM]]+Table1[[#This Row],[IMT17]]+Table1[[#This Row],[IMT252]]+Table1[[#This Row],[IMT28]]+Table1[[#This Row],[IMT29]]+Table1[[#This Row],[LIABILITY PREMIUM]]+Table1[[#This Row],[TOTAL GST]] -> 51997.74
A10: 9 | B10: 46043 | C10: GJ-12-BX-8779 | D10: AVO/2315/20034797 | E10: 46043 | F10: 46407 | G10: 61J68495258 | H10: MAT447228G5J95185 | I10: TATA MOTORS LTD / TATA LPS 4018 | J10: 5883 / 45500 | K10: 2016 / 24-11-2016 | L10: 1600000 | M10: 10000 | N10: 0 | O10: =Table1[[#This Row],[VEHICLE IDV]]+Table1[[#This Row],[ELECTRICAL ACCESSORIES IDV]]+Table1[[#This Row],[CNG KIT IDV]] -> 1610000 | P10: 3804 | Q10: 571 | R10: 400 | S10: 0 | T10: 0 | U10: =SUM(Table1[[#This Row],[OD PREMIUM]:[No Claim Bonus]]) -> 4775 | V10: 50 | W10: 0 | X10: 50 | Y10: 0 | Z10: 44242 | AA10: =SUM(Table1[[#This Row],[TOTAL OD PREMIUM]:[IMT29]])*18%+Table1[[#This Row],[LIABILITY PREMIUM]]*5% -> 3089.6 | AB10: =Table1[[#This Row],[TOTAL OD PREMIUM]]+Table1[[#This Row],[IMT17]]+Table1[[#This Row],[IMT252]]+Table1[[#This Row],[IMT28]]+Table1[[#This Row],[IMT29]]+Table1[[#This Row],[LIABILITY PREMIUM]]+Table1[[#This Row],[TOTAL GST]] -> 52206.6
A11: 10 | B11: 46043 | C11: RJ-32-GB-5192 | D11: AVO/2315/20034067 | E11: 46043 | F11: 46407 | G11: B591803261C63504299 | H11: MAT447220G1C07205 | I11: TATA MOTORS LPS 4018 TC BS3 | J11: 5883 / 45500 | K11: 2016 / 12-04-2016 | L11: 1600000 | M11: 10000 | N11: 0 | O11: =Table1[[#This Row],[VEHICLE IDV]]+Table1[[#This Row],[ELECTRICAL ACCESSORIES IDV]]+Table1[[#This Row],[CNG KIT IDV]] -> 1610000 | P11: 3804 | Q11: 571 | R11: 400 | S11: 0 | T11: 0 | U11: =SUM(Table1[[#This Row],[OD PREMIUM]:[No Claim Bonus]]) -> 4775 | V11: 50 | W11: 0 | X11: 50 | Y11: 0 | Z11: 44242 | AA11: =SUM(Table1[[#This Row],[TOTAL OD PREMIUM]:[IMT29]])*18%+Table1[[#This Row],[LIABILITY PREMIUM]]*5% -> 3089.6 | AB11: =Table1[[#This Row],[TOTAL OD PREMIUM]]+Table1[[#This Row],[IMT17]]+Table1[[#This Row],[IMT252]]+Table1[[#This Row],[IMT28]]+Table1[[#This Row],[IMT29]]+Table1[[#This Row],[LIABILITY PREMIUM]]+Table1[[#This Row],[TOTAL GST]] -> 52206.6
A12: 11 | B12: 46045 | C12: GJ-16-AU-5412 | D12: 132/02/17/0127/MTP/1010339320 | E12: 46043 | F12: 46411 | G12: 400952D0061569 | H12: MEC2246CDJP061760 | I12: BHARAT BENZ 3123 R 8X2 | J12: 6372 / 35000 | K12: 2018 / 13-06-2018 | L12: 1140000 | M12: 10000 | N12: 0 | O12: =Table1[[#This Row],[VEHICLE IDV]]+Table1[[#This Row],[ELECTRICAL ACCESSORIES IDV]]+Table1[[#This Row],[CNG KIT IDV]] -> 1150000 | P12: 2687 | Q12: 430 | R12: 181 | S12: 0 | T12: 0 | U12: =SUM(Table1[[#This Row],[OD PREMIUM]:[No Claim Bonus]]) -> 3298 | V12: 60 | W12: 0 | X12: 50 | Y12: 0 | Z12: 43950 | AA12: =SUM(Table1[[#This Row],[TOTAL OD PREMIUM]:[IMT29]])*18%+Table1[[#This Row],[LIABILITY PREMIUM]]*5% -> 2810.94 | AB12: =Table1[[#This Row],[TOTAL OD PREMIUM]]+Table1[[#This Row],[IMT17]]+Table1[[#This Row],[IMT252]]+Table1[[#This Row],[IMT28]]+Table1[[#This Row],[IMT29]]+Table1[[#This Row],[LIABILITY PREMIUM]]+Table1[[#This Row],[TOTAL GST]] -> 50168.94
A13: 12 | B13: 46049 | C13: GJ-18-AV-4737 | D13: AVO/2315/20040069 | E13: 46052 | F13: 46416 | G13: 40M62376990 | H13: 426021AUZ702036 | I13: TATA MOTORS LTD LPT2515TC EX48806 2RHD B2 1210 | J13: 5883 / 28000 | K13: 2005 / 07-02-2005 | L13: 443739 | M13: 10000 | N13: 0 | O13: =Table1[[#This Row],[VEHICLE IDV]]+Table1[[#This Row],[ELECTRICAL ACCESSORIES IDV]]+Table1[[#This Row],[CNG KIT IDV]] -> 453739 | P13: 1244 | Q13: 187 | R13: 400 | S13: 0 | T13: -366 | U13: =SUM(Table1[[#This Row],[OD PREMIUM]:[No Claim Bonus]]) -> 1465 | V13: 50 | W13: 0 | X13: 50 | Y13: 0 | Z13: 43950 | AA13: =SUM(Table1[[#This Row],[TOTAL OD PREMIUM]:[IMT29]])*18%+Table1[[#This Row],[LIABILITY PREMIUM]]*5% -> 2479.2 | AB13: =Table1[[#This Row],[TOTAL OD PREMIUM]]+Table1[[#This Row],[IMT17]]+Table1[[#This Row],[IMT252]]+Table1[[#This Row],[IMT28]]+Table1[[#This Row],[IMT29]]+Table1[[#This Row],[LIABILITY PREMIUM]]+Table1[[#This Row],[TOTAL GST]] -> 47994.2
A14: 13 | B14: 46055 | C14: GJ-12-Z-1317 | D14: AVO/2315/20047578 | E14: 46058 | F14: 46422 | G14: 70K62608759 | H14: 415206KSZ225493 | I14: TATA LPS3516 TC32 EX | J14: 5883 / 39500 | K14: 2007 / 28-12-2007 | L14: 520000 | M14: 10000 | N14: 0 | O14: =Table1[[#This Row],[VEHICLE IDV]]+Table1[[#This Row],[ELECTRICAL ACCESSORIES IDV]]+Table1[[#This Row],[CNG KIT IDV]] -> 530000 | P14: 1685 | Q14: 253 | R14: 400 | S14: 0 | T14: -1169 | U14: =SUM(Table1[[#This Row],[OD PREMIUM]:[No Claim Bonus]]) -> 1169 | V14: 50 | W14: 0 | X14: 50 | Y14: 0 | Z14: 43950 | AA14: =SUM(Table1[[#This Row],[TOTAL OD PREMIUM]:[IMT29]])*18%+Table1[[#This Row],[LIABILITY PREMIUM]]*5% -> 2425.92 | AB14: =Table1[[#This Row],[TOTAL OD PREMIUM]]+Table1[[#This Row],[IMT17]]+Table1[[#This Row],[IMT252]]+Table1[[#This Row],[IMT28]]+Table1[[#This Row],[IMT29]]+Table1[[#This Row],[LIABILITY PREMIUM]]+Table1[[#This Row],[TOTAL GST]] -> 47644.92
A15: 14 | B15: 46059 | C15: GJ-18-AZ-5588 | D15: VGC1490403000100 | E15: 46060 | F15: 46424 | G15: 71K84423173 | H15: MAT503020HAN13178 | I15: TATA LPS3518 CR | J15: 5883 / 39500 | K15: 2018 / 26-02-2018 | L15: 2049000 | M15: 311000 | N15: 50000 | O15: =Table1[[#This Row],[VEHICLE IDV]]+Table1[[#This Row],[ELECTRICAL ACCESSORIES IDV]]+Table1[[#This Row],[CNG KIT IDV]] -> 2410000 | P15: =3749+743 -> 4492 | Q15: 1059 | R15: 569 | S15: 2000 | T15: -4060 | U15: =SUM(Table1[[#This Row],[OD PREMIUM]:[No Claim Bonus]]) -> 4060 | V15: 60 | W15: 60 | X15: 50 | Y15: 50 | Z15: 43950 | AA15: =SUM(Table1[[#This Row],[TOTAL OD PREMIUM]:[IMT29]])*18%+Table1[[#This Row],[LIABILITY PREMIUM]]*5% -> 2967.9 | AB15: =Table1[[#This Row],[TOTAL OD PREMIUM]]+Table1[[#This Row],[IMT17]]+Table1[[#This Row],[IMT252]]+Table1[[#This Row],[IMT28]]+Table1[[#This Row],[IMT29]]+Table1[[#This Row],[LIABILITY PREMIUM]]+Table1[[#This Row],[TOTAL GST]] -> 51197.9
A16: 15 | B16: 46074 | C16: GJ-12-Z-2989 | D16: AVO/2315/20069965 | E16: 46077 | F16: 46441 | G16: 80G62696392 | H16: 415206GRZ219067 | I16: TATA MOTORS LTD LPS3516TC EX ABS3200 | J16: 5883/39500 | K16: 2008 / 25-09-2008 | L16: 487000 | M16: 10000 | N16: 0 | O16: =Table1[[#This Row],[VEHICLE IDV]]+Table1[[#This Row],[ELECTRICAL ACCESSORIES IDV]] -> 497000 | P16: 1625 | Q16: 244 | R16: 400 | S16: 0 | T16: -567 | U16: =SUM(Table1[[#This Row],[OD PREMIUM]:[No Claim Bonus]]) -> 1702 | V16: 50 | W16: 0 | X16: 50 | Y16: 0 | Z16: 43950 | AA16: =SUM(Table1[[#This Row],[TOTAL OD PREMIUM]:[IMT29]])*18%+Table1[[#This Row],[LIABILITY PREMIUM]]*5% -> 2521.86 | AB16: =Table1[[#This Row],[TOTAL OD PREMIUM]]+Table1[[#This Row],[IMT17]]+Table1[[#This Row],[IMT252]]+Table1[[#This Row],[IMT28]]+Table1[[#This Row],[IMT29]]+Table1[[#This Row],[LIABILITY PREMIUM]]+Table1[[#This Row],[TOTAL GST]] -> 48273.86
A17: 16 | B17: 46104 | C17: GJ-18-AZ-0849 | D17: 3379/04676162/000/00 | E17: 46106 | F17: 46470 | G17: 51H84248310 | H17: MAT503017FAN12557 | I17: TATA MOTORS,LPS 3518-TC BS III HAULAGE TRACTOR SLPR CAB | J17: 5883 / 39500 | K17: 2015 / 10-05-2016 | L17: 1368000 | M17: 10000 | N17: 0 | O17: =Table1[[#This Row],[VEHICLE IDV]]+Table1[[#This Row],[ELECTRICAL ACCESSORIES IDV]] -> 1378000 | P17: 2637 | Q17: 396 | R17: 0 | S17: 3420 | T17: 0 | U17: =SUM(Table1[[#This Row],[OD PREMIUM]:[No Claim Bonus]]) -> 6453 | V17: 50 | W17: 0 | X17: 50 | Y17: 0 | Z17: 43950 | AA17: =SUM(Table1[[#This Row],[TOTAL OD PREMIUM]:[IMT29]])*18%+Table1[[#This Row],[LIABILITY PREMIUM]]*5% -> 3377.04 | AB17: =Table1[[#This Row],[TOTAL OD PREMIUM]]+Table1[[#This Row],[IMT17]]+Table1[[#This Row],[IMT252]]+Table1[[#This Row],[IMT28]]+Table1[[#This Row],[IMT29]]+Table1[[#This Row],[LIABILITY PREMIUM]]+Table1[[#This Row],[TOTAL GST]] -> 53880.04
A18: 17 | B18: 46104 | C18: GJ-12-Z-1089 | D18: AVO/2315/20102500 | E18: 46107 | F18: 46471 | G18: 614459 | H18: 226468 | I18: TATA MOTORS LTD LPS*3516TC EX ABS*CAB4*2*RAD | J18: 5883 / 39200 | K18: 2007 / 27-11-2007 | L18: 466000 | M18: 10000 | N18: 0 | O18: =Table1[[#This Row],[VEHICLE IDV]]+Table1[[#This Row],[ELECTRICAL ACCESSORIES IDV]] -> 476000 | P18: 1578 | Q18: 237 | R18: 400 | S18: 0 | T18: -775 | U18: =SUM(Table1[[#This Row],[OD PREMIUM]:[No Claim Bonus]]) -> 1440 | V18: 0 | W18: 0 | X18: 100 | Y18: 0 | Z18: 43950 | AA18: =SUM(Table1[[#This Row],[TOTAL OD PREMIUM]:[IMT29]])*18%+Table1[[#This Row],[LIABILITY PREMIUM]]*5% -> 2474.7 | AB18: =Table1[[#This Row],[TOTAL OD PREMIUM]]+Table1[[#This Row],[IMT17]]+Table1[[#This Row],[IMT252]]+Table1[[#This Row],[IMT28]]+Table1[[#This Row],[IMT29]]+Table1[[#This Row],[LIABILITY PREMIUM]]+Table1[[#This Row],[TOTAL GST]] -> 47964.7
A19: 18 | B19: 46106 | C19: GJ-18-AZ-4229 | D19: AVO/2315/20104965 | E19: 46110 | F19: 46474 | G19: B591803231C63317658 | H19: MAT447220D3C06249 | I19: TATA MOTORS LPS 4018 TC BS3 | J19: 5883 / 45500 | K19: 2013 / 21-06-2013 | L19: 900000 | M19: 10000 | N19: 0 | O19: =Table1[[#This Row],[VEHICLE IDV]]+Table1[[#This Row],[ELECTRICAL ACCESSORIES IDV]] -> 910000 | P19: 2552 | Q19: 383 | R19: 400 | S19: 0 | T19: -1667 | U19: =SUM(Table1[[#This Row],[OD PREMIUM]:[No Claim Bonus]]) -> 1668 | V19: 0 | W19: 0 | X19: 100 | Y19: 0 | Z19: 44242 | AA19: =SUM(Table1[[#This Row],[TOTAL OD PREMIUM]:[IMT29]])*18%+Table1[[#This Row],[LIABILITY PREMIUM]]*5% -> 2530.34 | AB19: =Table1[[#This Row],[TOTAL OD PREMIUM]]+Table1[[#This Row],[IMT17]]+Table1[[#This Row],[IMT252]]+Table1[[#This Row],[IMT28]]+Table1[[#This Row],[IMT29]]+Table1[[#This Row],[LIABILITY PREMIUM]]+Table1[[#This Row],[TOTAL GST]] -> 48540.34
A20: 19 | B20: 46107 | C20: GJ-12-Z-1090 | D20: AVO/2315/20107139 | E20: 46112 | F20: 46476 | G20: 614996 | H20: 226607 | I20: TATA MOTORS LTD LPS*3516TC EX ABS*CAB4*2* RAD | J20: 5883 / 39500 | K20: 2007 / 27-11-2007 | L20: 466000 | M20: 10000 | N20: 0 | O20: =Table1[[#This Row],[VEHICLE IDV]]+Table1[[#This Row],[ELECTRICAL ACCESSORIES IDV]] -> 476000 | P20: 1587 | Q20: 238 | R20: 400 | S20: 0 | T20: -1001 | U20: =SUM(Table1[[#This Row],[OD PREMIUM]:[No Claim Bonus]]) -> 1224 | V20: 0 | W20: 0 | X20: 100 | Y20: 0 | Z20: 43950 | AA20: =SUM(Table1[[#This Row],[TOTAL OD PREMIUM]:[IMT29]])*18%+Table1[[#This Row],[LIABILITY PREMIUM]]*5% -> 2435.82 | AB20: =Table1[[#This Row],[TOTAL OD PREMIUM]]+Table1[[#This Row],[IMT17]]+Table1[[#This Row],[IMT252]]+Table1[[#This Row],[IMT28]]+Table1[[#This Row],[IMT29]]+Table1[[#This Row],[LIABILITY PREMIUM]]+Table1[[#This Row],[TOTAL GST]] -> 47709.82
A21: 20 | B21: 46115 | C21: GJ-18-AV-4735 | D21: AVO/2315/20117977 | E21: 46119 | F21: 46483 | G21: 50A62380335 | H21: 021AUZ702184 | I21: TATA MOTORS LTD LPT2515TC EX48806*2RH D B2 1210 | J21: 5883 / 25000 | K21: 2005 / 07-02-2005 | L21: 342000 | M21: 10000 | N21: 0 | O21: =Table1[[#This Row],[VEHICLE IDV]]+Table1[[#This Row],[ELECTRICAL ACCESSORIES IDV]] -> 352000 | P21: 977 | Q21: 147 | R21: 400 | S21: 0 | T21: -762 | U21: =SUM(Table1[[#This Row],[OD PREMIUM]:[No Claim Bonus]]) -> 762 | V21: 0 | W21: 0 | X21: 100 | Y21: 0 | Z21: 43950 | AA21: =SUM(Table1[[#This Row],[TOTAL OD PREMIUM]:[IMT29]])*18%+Table1[[#This Row],[LIABILITY PREMIUM]]*5% -> 2352.66 | AB21: =Table1[[#This Row],[TOTAL OD PREMIUM]]+Table1[[#This Row],[IMT17]]+Table1[[#This Row],[IMT252]]+Table1[[#This Row],[IMT28]]+Table1[[#This Row],[IMT29]]+Table1[[#This Row],[LIABILITY PREMIUM]]+Table1[[#This Row],[TOTAL GST]] -> 47164.66
A22: 21 | B22: 46127 | C22: GJ-09-Z-4266 | D22: AVO/2315/20128523 | E22: 46128 | F22: 46492 | G22: 11M63216432 | H22: MAT466385C5A01411 | I22: TATA MOTORS LTD LPT3118TC BS2 COWL | J22: 5883 / 35000 | K22: 2012 / 27-02-2012 | L22: 1115000 | M22: 10000 | N22: 0 | O22: =Table1[[#This Row],[VEHICLE IDV]]+Table1[[#This Row],[ELECTRICAL ACCESSORIES IDV]] -> 1125000 | P22: 2641 | Q22: 396 | R22: 400 | S22: 0 | T22: -1203 | U22: =SUM(Table1[[#This Row],[OD PREMIUM]:[No Claim Bonus]]) -> 2234 | V22: 0 | W22: 0 | X22: 100 | Y22: 0 | Z22: 43950 | AA22: =SUM(Table1[[#This Row],[TOTAL OD PREMIUM]:[IMT29]])*18%+Table1[[#This Row],[LIABILITY PREMIUM]]*5% -> 2617.62 | AB22: =Table1[[#This Row],[TOTAL OD PREMIUM]]+Table1[[#This Row],[IMT17]]+Table1[[#This Row],[IMT252]]+Table1[[#This Row],[IMT28]]+Table1[[#This Row],[IMT29]]+Table1[[#This Row],[LIABILITY PREMIUM]]+Table1[[#This Row],[TOTAL GST]] -> 48901.62
A23: 22 | B23: 46135 | C23: GJ-12-BT-7142 | D23: 213001/31/27/001982 | E23: 46137 | F23: 46501 | G23: GEPZ109222 | H23: MB1TRVHD0GPES9238 | I23: ASHOK LEYLAND - U 4019 IL FBV TRI AXLE FLAT BED TRAILER / DIESEL | J23: 5760 / 45500 | K23: 2016 / 06-06-2016 | L23: 1740000 | M23: 0 | N23: 0 | O23: =Table1[[#This Row],[VEHICLE IDV]]+Table1[[#This Row],[ELECTRICAL ACCESSORIES IDV]] -> 1740000 | P23: 3733 | Q23: 0 | R23: 0 | S23: 0 | T23: 0 | U23: =SUM(Table1[[#This Row],[OD PREMIUM]:[No Claim Bonus]]) -> 3733 | V23: 315 | W23: 75 | X23: 75 | Y23: 0 | Z23: 44242 | AA23: =SUM(Table1[[#This Row],[TOTAL OD PREMIUM]:[IMT29]])*18%+Table1[[#This Row],[LIABILITY PREMIUM]]*5% -> 2967.74 | AB23: =Table1[[#This Row],[TOTAL OD PREMIUM]]+Table1[[#This Row],[IMT17]]+Table1[[#This Row],[IMT252]]+Table1[[#This Row],[IMT28]]+Table1[[#This Row],[IMT29]]+Table1[[#This Row],[LIABILITY PREMIUM]]+Table1[[#This Row],[TOTAL GST]] -> 51407.74
A24: 23 | B24: 46137 | C24: GJ-18-BV-9156 | D24: AVO/2315/20137869 | E24: 46141 | F24: 46505 | G24: 21G63271258 | H24: MAT503010CAG05738 | I24: TATA MOTORS LTD LPS3518TC/32 TIPPER | J24: 5883 / 39500 | K24: 2012 / 04-09-2012 | L24: 1080000 | M24: 10000 | N24: 0 | O24: =Table1[[#This Row],[VEHICLE IDV]]+Table1[[#This Row],[ELECTRICAL ACCESSORIES IDV]] -> 1090000 | P24: 2719 | Q24: 408 | R24: 400 | S24: 0 | T24: -882 | U24: =SUM(Table1[[#This Row],[OD PREMIUM]:[No Claim Bonus]]) -> 2645 | V24: 0 | W24: 0 | X24: 100 | Y24: 0 | Z24: 43950 | AA24: =SUM(Table1[[#This Row],[TOTAL OD PREMIUM]:[IMT29]])*18%+Table1[[#This Row],[LIABILITY PREMIUM]]*5% -> 2691.6 | AB24: =Table1[[#This Row],[TOTAL OD PREMIUM]]+Table1[[#This Row],[IMT17]]+Table1[[#This Row],[IMT252]]+Table1[[#This Row],[IMT28]]+Table1[[#This Row],[IMT29]]+Table1[[#This Row],[LIABILITY PREMIUM]]+Table1[[#This Row],[TOTAL GST]] -> 49386.6 | AC24: TIPPER STATUS PENDING IN RC
A25: 24 | B25: 46155 | C25: GJ-18-BV-8816 | D25: AVO/2315/20151800 | E25: 46159 | F25: 46523 | G25: 61G84322207 | H25: MAT447224G5G12208 | I25: TATA MOTORS LPS 4018 CR BS IV GVW 45500 | J25: 5883 /45500 | K25: 2016 / 03-10-2016 | L25: 1500000 | M25: 10000 | N25: 0 | O25: =Table1[[#This Row],[VEHICLE IDV]]+Table1[[#This Row],[ELECTRICAL ACCESSORIES IDV]] -> 1510000 | P25: 3650 | Q25: 548 | R25: 400 | S25: 0 | T25: 0 | U25: =SUM(Table1[[#This Row],[OD PREMIUM]:[No Claim Bonus]]) -> 4598 | V25: 0 | W25: 0 | X25: 100 | Y25: 0 | Z25: 44242 | AA25: =SUM(Table1[[#This Row],[TOTAL OD PREMIUM]:[IMT29]])*18%+Table1[[#This Row],[LIABILITY PREMIUM]]*5% -> 3057.74 | AB25: =Table1[[#This Row],[TOTAL OD PREMIUM]]+Table1[[#This Row],[IMT17]]+Table1[[#This Row],[IMT252]]+Table1[[#This Row],[IMT28]]+Table1[[#This Row],[IMT29]]+Table1[[#This Row],[LIABILITY PREMIUM]]+Table1[[#This Row],[TOTAL GST]] -> 51997.74 | AC25: TIPPER STATUS PENDING IN RC
A26: 25 | B26: 46174 | C26: GJ-18-AV-7468 | D26: VGC1555394000100 | E26: 46175 | F26: 46539 | G26: B591803231C63316371 | H26: MAT447220D3C05567 | I26: TATA MOTORS LPS 4018 TIPPER | J26: 5883 /45500 | K26: 2013 / 18-06-2013 | L26: 1050000 | M26: 0 | N26: 0 | O26: =Table1[[#This Row],[VEHICLE IDV]]+Table1[[#This Row],[ELECTRICAL ACCESSORIES IDV]] -> 1050000 | P26: 2827 | Q26: 424 | R26: 0 | S26: 2625 | T26: -1625 | U26: =SUM(Table1[[#This Row],[OD PREMIUM]:[No Claim Bonus]]) -> 4251 | V26: 0 | W26: 0 | X26: 50 | Y26: 50 | Z26: 44242 | AA26: =SUM(Table1[[#This Row],[TOTAL OD PREMIUM]:[IMT29]])*18%+Table1[[#This Row],[LIABILITY PREMIUM]]*5% -> 2995.28 | AB26: =Table1[[#This Row],[TOTAL OD PREMIUM]]+Table1[[#This Row],[IMT17]]+Table1[[#This Row],[IMT252]]+Table1[[#This Row],[IMT28]]+Table1[[#This Row],[IMT29]]+Table1[[#This Row],[LIABILITY PREMIUM]]+Table1[[#This Row],[TOTAL GST]] -> 51588.28
A27: 26 | C27: GJ-18-AX-6955 | L27: 0 | M27: 0 | N27: 0 | O27: =Table1[[#This Row],[VEHICLE IDV]]+Table1[[#This Row],[ELECTRICAL ACCESSORIES IDV]] -> 0 | P27: 0 | Q27: 0 | R27: 0 | S27: 0 | T27: 0 | U27: =SUM(Table1[[#This Row],[OD PREMIUM]:[No Claim Bonus]]) -> 0 | V27: 0 | W27: 0 | X27: 0 | Y27: 0 | Z27: 0 | AA27: =SUM(Table1[[#This Row],[TOTAL OD PREMIUM]:[IMT29]])*18%+Table1[[#This Row],[LIABILITY PREMIUM]]*5% -> 0 | AB27: =Table1[[#This Row],[TOTAL OD PREMIUM]]+Table1[[#This Row],[IMT17]]+Table1[[#This Row],[IMT252]]+Table1[[#This Row],[IMT28]]+Table1[[#This Row],[IMT29]]+Table1[[#This Row],[LIABILITY PREMIUM]]+Table1[[#This Row],[TOTAL GST]] -> 0 | AC27: TIPPER STATUS PENDING IN RC
A28: 27 | L28: 0 | M28: 0 | N28: 0 | O28: =Table1[[#This Row],[VEHICLE IDV]]+Table1[[#This Row],[ELECTRICAL ACCESSORIES IDV]] -> 0 | P28: 0 | Q28: 0 | R28: 0 | S28: 0 | T28: 0 | U28: =SUM(Table1[[#This Row],[OD PREMIUM]:[No Claim Bonus]]) -> 0 | V28: 0 | W28: 0 | X28: 0 | Y28: 0 | Z28: 0 | AA28: =SUM(Table1[[#This Row],[TOTAL OD PREMIUM]:[IMT29]])*18%+Table1[[#This Row],[LIABILITY PREMIUM]]*5% -> 0 | AB28: =Table1[[#This Row],[TOTAL OD PREMIUM]]+Table1[[#This Row],[IMT17]]+Table1[[#This Row],[IMT252]]+Table1[[#This Row],[IMT28]]+Table1[[#This Row],[IMT29]]+Table1[[#This Row],[LIABILITY PREMIUM]]+Table1[[#This Row],[TOTAL GST]] -> 0
A29: 28 | L29: 0 | M29: 0 | N29: 0 | O29: =Table1[[#This Row],[VEHICLE IDV]]+Table1[[#This Row],[ELECTRICAL ACCESSORIES IDV]] -> 0 | P29: 0 | Q29: 0 | R29: 0 | S29: 0 | T29: 0 | U29: =SUM(Table1[[#This Row],[OD PREMIUM]:[No Claim Bonus]]) -> 0 | V29: 0 | W29: 0 | X29: 0 | Y29: 0 | Z29: 0 | AA29: =SUM(Table1[[#This Row],[TOTAL OD PREMIUM]:[IMT29]])*18%+Table1[[#This Row],[LIABILITY PREMIUM]]*5% -> 0 | AB29: =Table1[[#This Row],[TOTAL OD PREMIUM]]+Table1[[#This Row],[IMT17]]+Table1[[#This Row],[IMT252]]+Table1[[#This Row],[IMT28]]+Table1[[#This Row],[IMT29]]+Table1[[#This Row],[LIABILITY PREMIUM]]+Table1[[#This Row],[TOTAL GST]] -> 0
A30: 29 | L30: 0 | M30: 0 | N30: 0 | O30: =Table1[[#This Row],[VEHICLE IDV]]+Table1[[#This Row],[ELECTRICAL ACCESSORIES IDV]] -> 0 | P30: 0 | Q30: 0 | R30: 0 | S30: 0 | T30: 0 | U30: =SUM(Table1[[#This Row],[OD PREMIUM]:[No Claim Bonus]]) -> 0 | V30: 0 | W30: 0 | X30: 0 | Y30: 0 | Z30: 0 | AA30: =SUM(Table1[[#This Row],[TOTAL OD PREMIUM]:[IMT29]])*18%+Table1[[#This Row],[LIABILITY PREMIUM]]*5% -> 0 | AB30: =Table1[[#This Row],[TOTAL OD PREMIUM]]+Table1[[#This Row],[IMT17]]+Table1[[#This Row],[IMT252]]+Table1[[#This Row],[IMT28]]+Table1[[#This Row],[IMT29]]+Table1[[#This Row],[LIABILITY PREMIUM]]+Table1[[#This Row],[TOTAL GST]] -> 0
A31: 30 | L31: 0 | M31: 0 | N31: 0 | O31: =Table1[[#This Row],[VEHICLE IDV]]+Table1[[#This Row],[ELECTRICAL ACCESSORIES IDV]] -> 0 | P31: 0 | Q31: 0 | R31: 0 | S31: 0 | T31: 0 | U31: =SUM(Table1[[#This Row],[OD PREMIUM]:[No Claim Bonus]]) -> 0 | V31: 0 | W31: 0 | X31: 0 | Y31: 0 | Z31: 0 | AA31: =SUM(Table1[[#This Row],[TOTAL OD PREMIUM]:[IMT29]])*18%+Table1[[#This Row],[LIABILITY PREMIUM]]*5% -> 0 | AB31: =Table1[[#This Row],[TOTAL OD PREMIUM]]+Table1[[#This Row],[IMT17]]+Table1[[#This Row],[IMT252]]+Table1[[#This Row],[IMT28]]+Table1[[#This Row],[IMT29]]+Table1[[#This Row],[LIABILITY PREMIUM]]+Table1[[#This Row],[TOTAL GST]] -> 0
A32: 31 | L32: 0 | M32: 0 | N32: 0 | O32: =Table1[[#This Row],[VEHICLE IDV]]+Table1[[#This Row],[ELECTRICAL ACCESSORIES IDV]] -> 0 | P32: 0 | Q32: 0 | R32: 0 | S32: 0 | T32: 0 | U32: =SUM(Table1[[#This Row],[OD PREMIUM]:[No Claim Bonus]]) -> 0 | V32: 0 | W32: 0 | X32: 0 | Y32: 0 | Z32: 0 | AA32: =SUM(Table1[[#This Row],[TOTAL OD PREMIUM]:[IMT29]])*18%+Table1[[#This Row],[LIABILITY PREMIUM]]*5% -> 0 | AB32: =Table1[[#This Row],[TOTAL OD PREMIUM]]+Table1[[#This Row],[IMT17]]+Table1[[#This Row],[IMT252]]+Table1[[#This Row],[IMT28]]+Table1[[#This Row],[IMT29]]+Table1[[#This Row],[LIABILITY PREMIUM]]+Table1[[#This Row],[TOTAL GST]] -> 0
A33: 32 | L33: 0 | M33: 0 | N33: 0 | O33: =Table1[[#This Row],[VEHICLE IDV]]+Table1[[#This Row],[ELECTRICAL ACCESSORIES IDV]] -> 0 | P33: 0 | Q33: 0 | R33: 0 | S33: 0 | T33: 0 | U33: =SUM(Table1[[#This Row],[OD PREMIUM]:[No Claim Bonus]]) -> 0 | V33: 0 | W33: 0 | X33: 0 | Y33: 0 | Z33: 0 | AA33: =SUM(Table1[[#This Row],[TOTAL OD PREMIUM]:[IMT29]])*18%+Table1[[#This Row],[LIABILITY PREMIUM]]*5% -> 0 | AB33: =Table1[[#This Row],[TOTAL OD PREMIUM]]+Table1[[#This Row],[IMT17]]+Table1[[#This Row],[IMT252]]+Table1[[#This Row],[IMT28]]+Table1[[#This Row],[IMT29]]+Table1[[#This Row],[LIABILITY PREMIUM]]+Table1[[#This Row],[TOTAL GST]] -> 0
A34: 33 | L34: 0 | M34: 0 | N34: 0 | O34: =Table1[[#This Row],[VEHICLE IDV]]+Table1[[#This Row],[ELECTRICAL ACCESSORIES IDV]] -> 0 | P34: 0 | Q34: 0 | R34: 0 | S34: 0 | T34: 0 | U34: =SUM(Table1[[#This Row],[OD PREMIUM]:[No Claim Bonus]]) -> 0 | V34: 0 | W34: 0 | X34: 0 | Y34: 0 | Z34: 0 | AA34: =SUM(Table1[[#This Row],[TOTAL OD PREMIUM]:[IMT29]])*18%+Table1[[#This Row],[LIABILITY PREMIUM]]*5% -> 0 | AB34: =Table1[[#This Row],[TOTAL OD PREMIUM]]+Table1[[#This Row],[IMT17]]+Table1[[#This Row],[IMT252]]+Table1[[#This Row],[IMT28]]+Table1[[#This Row],[IMT29]]+Table1[[#This Row],[LIABILITY PREMIUM]]+Table1[[#This Row],[TOTAL GST]] -> 0
A35: 34 | L35: 0 | M35: 0 | N35: 0 | O35: =Table1[[#This Row],[VEHICLE IDV]]+Table1[[#This Row],[ELECTRICAL ACCESSORIES IDV]] -> 0 | P35: 0 | Q35: 0 | R35: 0 | S35: 0 | T35: 0 | U35: =SUM(Table1[[#This Row],[OD PREMIUM]:[No Claim Bonus]]) -> 0 | V35: 0 | W35: 0 | X35: 0 | Y35: 0 | Z35: 0 | AA35: =SUM(Table1[[#This Row],[TOTAL OD PREMIUM]:[IMT29]])*18%+Table1[[#This Row],[LIABILITY PREMIUM]]*5% -> 0 | AB35: =Table1[[#This Row],[TOTAL OD PREMIUM]]+Table1[[#This Row],[IMT17]]+Table1[[#This Row],[IMT252]]+Table1[[#This Row],[IMT28]]+Table1[[#This Row],[IMT29]]+Table1[[#This Row],[LIABILITY PREMIUM]]+Table1[[#This Row],[TOTAL GST]] -> 0
A36: 35 | L36: 0 | M36: 0 | N36: 0 | O36: =Table1[[#This Row],[VEHICLE IDV]]+Table1[[#This Row],[ELECTRICAL ACCESSORIES IDV]] -> 0 | P36: 0 | Q36: 0 | R36: 0 | S36: 0 | T36: 0 | U36: =SUM(Table1[[#This Row],[OD PREMIUM]:[No Claim Bonus]]) -> 0 | V36: 0 | W36: 0 | X36: 0 | Y36: 0 | Z36: 0 | AA36: =SUM(Table1[[#This Row],[TOTAL OD PREMIUM]:[IMT29]])*18%+Table1[[#This Row],[LIABILITY PREMIUM]]*5% -> 0 | AB36: =Table1[[#This Row],[TOTAL OD PREMIUM]]+Table1[[#This Row],[IMT17]]+Table1[[#This Row],[IMT252]]+Table1[[#This Row],[IMT28]]+Table1[[#This Row],[IMT29]]+Table1[[#This Row],[LIABILITY PREMIUM]]+Table1[[#This Row],[TOTAL GST]] -> 0
A37: 36 | L37: 0 | M37: 0 | N37: 0 | O37: =Table1[[#This Row],[VEHICLE IDV]]+Table1[[#This Row],[ELECTRICAL ACCESSORIES IDV]] -> 0 | P37: 0 | Q37: 0 | R37: 0 | S37: 0 | T37: 0 | U37: =SUM(Table1[[#This Row],[OD PREMIUM]:[No Claim Bonus]]) -> 0 | V37: 0 | W37: 0 | X37: 0 | Y37: 0 | Z37: 0 | AA37: =SUM(Table1[[#This Row],[TOTAL OD PREMIUM]:[IMT29]])*18%+Table1[[#This Row],[LIABILITY PREMIUM]]*5% -> 0 | AB37: =Table1[[#This Row],[TOTAL OD PREMIUM]]+Table1[[#This Row],[IMT17]]+Table1[[#This Row],[IMT252]]+Table1[[#This Row],[IMT28]]+Table1[[#This Row],[IMT29]]+Table1[[#This Row],[LIABILITY PREMIUM]]+Table1[[#This Row],[TOTAL GST]] -> 0
A38: 37 | L38: 0 | M38: 0 | N38: 0 | O38: =Table1[[#This Row],[VEHICLE IDV]]+Table1[[#This Row],[ELECTRICAL ACCESSORIES IDV]] -> 0 | P38: 0 | Q38: 0 | R38: 0 | S38: 0 | T38: 0 | U38: =SUM(Table1[[#This Row],[OD PREMIUM]:[No Claim Bonus]]) -> 0 | V38: 0 | W38: 0 | X38: 0 | Y38: 0 | Z38: 0 | AA38: =SUM(Table1[[#This Row],[TOTAL OD PREMIUM]:[IMT29]])*18%+Table1[[#This Row],[LIABILITY PREMIUM]]*5% -> 0 | AB38: =Table1[[#This Row],[TOTAL OD PREMIUM]]+Table1[[#This Row],[IMT17]]+Table1[[#This Row],[IMT252]]+Table1[[#This Row],[IMT28]]+Table1[[#This Row],[IMT29]]+Table1[[#This Row],[LIABILITY PREMIUM]]+Table1[[#This Row],[TOTAL GST]] -> 0
A39: 38 | L39: 0 | M39: 0 | N39: 0 | O39: =Table1[[#This Row],[VEHICLE IDV]]+Table1[[#This Row],[ELECTRICAL ACCESSORIES IDV]] -> 0 | P39: 0 | Q39: 0 | R39: 0 | S39: 0 | T39: 0 | U39: =SUM(Table1[[#This Row],[OD PREMIUM]:[No Claim Bonus]]) -> 0 | V39: 0 | W39: 0 | X39: 0 | Y39: 0 | Z39: 0 | AA39: =SUM(Table1[[#This Row],[TOTAL OD PREMIUM]:[IMT29]])*18%+Table1[[#This Row],[LIABILITY PREMIUM]]*5% -> 0 | AB39: =Table1[[#This Row],[TOTAL OD PREMIUM]]+Table1[[#This Row],[IMT17]]+Table1[[#This Row],[IMT252]]+Table1[[#This Row],[IMT28]]+Table1[[#This Row],[IMT29]]+Table1[[#This Row],[LIABILITY PREMIUM]]+Table1[[#This Row],[TOTAL GST]] -> 0
... A41: 40 | L41: 0 | M41: 0 | N41: 0 | O41: =Table1[[#This Row],[VEHICLE IDV]]+Table1[[#This Row],[ELECTRICAL ACCESSORIES IDV]] -> 0 | P41: 0 | Q41: 0 | R41: 0 | S41: 0 | T41: 0 | U41: =SUM(Table1[[#This Row],[OD PREMIUM]:[No Claim Bonus]]) -> 0 | V41: 0 | W41: 0 | X41: 0 | Y41: 0 | Z41: 0 | AA41: =SUM(Table1[[#This Row],[TOTAL OD PREMIUM]:[IMT29]])*18%+Table1[[#This Row],[LIABILITY PREMIUM]]*5% -> 0 | AB41: =Table1[[#This Row],[TOTAL OD PREMIUM]]+Table1[[#This Row],[IMT17]]+Table1[[#This Row],[IMT252]]+Table1[[#This Row],[IMT28]]+Table1[[#This Row],[IMT29]]+Table1[[#This Row],[LIABILITY PREMIUM]]+Table1[[#This Row],[TOTAL GST]] -> 0
...

Sheet Data-OLD
A1: Sr No | B1: REGISTRATION NUMBER | C1: VEHICLE IDV | D1: ELECTRICAL ACCESSORIES / CNG/LPG IDV | E1: TOTAL IDV (VALUE) | F1: OD PREMIUM | G1: IMT23 | H1: IMT24 | I1: IMT25 | J1: No Claim Bonus | K1: TOTAL OD PREMIUM | L1: IMT17 | M1: IMT28 | N1: LIABILITY PREMIUM | O1: TOTAL GST | P1: TOTAL POLICY PREMIUM
A2: 1 | B2: GJ-01-AU-4504 | C2: 472532 | D2: 0 | E2: ='Data-OLD'!$C2+'Data-OLD'!$D2 -> 472532 | F2: 1715 | G2: 0 | H2: 0 | I2: 0 | J2: 0 | K2: =SUM('Data-OLD'!$F2:$J2) -> 1715 | L2: 50 | M2: 50 | N2: 43750 | O2: =SUM('Data-OLD'!$K2+'Data-OLD'!$L2+'Data-OLD'!$M2)*18%+'Data-OLD'!$N2*12% -> 5576.7 | P2: ='Data-OLD'!$K2+'Data-OLD'!$L2+'Data-OLD'!$M2+'Data-OLD'!$N2+'Data-OLD'!$O2 -> 51141.7
A3: 2 | B3: GJ-18-AV-8971 | C3: 700000 | D3: 0 | E3: ='Data-OLD'!$C3+'Data-OLD'!$D3 -> 700000 | F3: 3472 | G3: 521 | H3: 0 | I3: 0 | J3: -998 | K3: =SUM('Data-OLD'!$F3:$J3) -> 2995 | L3: 120 | M3: 100 | N3: 44242 | O3: =SUM('Data-OLD'!$K3+'Data-OLD'!$L3+'Data-OLD'!$M3)*18%+'Data-OLD'!$N3*12% -> 5887.74 | P3: ='Data-OLD'!$K3+'Data-OLD'!$L3+'Data-OLD'!$M3+'Data-OLD'!$N3+'Data-OLD'!$O3 -> 53344.74
A4: 3 | B4: GJ-18-BT-5220 | C4: 810000 | D4: 0 | E4: ='Data-OLD'!$C4+'Data-OLD'!$D4 -> 810000 | F4: 1663 | G4: 0 | H4: 0 | I4: 0 | J4: 0 | K4: =SUM('Data-OLD'!$F4:$J4) -> 1663 | L4: 75 | M4: 75 | N4: 43950 | O4: =SUM('Data-OLD'!$K4+'Data-OLD'!$L4+'Data-OLD'!$M4)*18%+'Data-OLD'!$N4*12% -> 5600.34 | P4: ='Data-OLD'!$K4+'Data-OLD'!$L4+'Data-OLD'!$M4+'Data-OLD'!$N4+'Data-OLD'!$O4 -> 51363.34
A5: 4 | B5: GJ-12-Z-3234 | C5: 900000 | D5: 0 | E5: ='Data-OLD'!$C5+'Data-OLD'!$D5 -> 900000 | F5: 4094 | G5: 0 | H5: 0 | I5: 0 | J5: -1023 | K5: =SUM('Data-OLD'!$F5:$J5) -> 3071 | L5: 50 | M5: 50 | N5: 43950 | O5: =SUM('Data-OLD'!$K5+'Data-OLD'!$L5+'Data-OLD'!$M5)*18%+'Data-OLD'!$N5*12% -> 5844.78 | P5: ='Data-OLD'!$K5+'Data-OLD'!$L5+'Data-OLD'!$M5+'Data-OLD'!$N5+'Data-OLD'!$O5 -> 52965.78
A6: 5 | B6: GJ-18-AX-0063 | C6: 710000 | D6: 100000 | E6: ='Data-OLD'!$C6+'Data-OLD'!$D6 -> 810000 | F6: 1279 | G6: 0 | H6: 0 | I6: 0 | J6: 0 | K6: =SUM('Data-OLD'!$F6:$J6) -> 1279 | L6: 75 | M6: 75 | N6: 43950 | O6: =SUM('Data-OLD'!$K6+'Data-OLD'!$L6+'Data-OLD'!$M6)*18%+'Data-OLD'!$N6*12% -> 5531.22 | P6: ='Data-OLD'!$K6+'Data-OLD'!$L6+'Data-OLD'!$M6+'Data-OLD'!$N6+'Data-OLD'!$O6 -> 50910.22
A7: 6 | B7: GJ-18-AZ-5394 | C7: 800000 | D7: 0 | E7: ='Data-OLD'!$C7+'Data-OLD'!$D7 -> 800000 | F7: 2207 | G7: 331 | H7: 0 | I7: 0 | J7: -1269 | K7: =SUM('Data-OLD'!$F7:$J7) -> 1269 | L7: 450 | M7: 100 | N7: 43950 | O7: =SUM('Data-OLD'!$K7+'Data-OLD'!$L7+'Data-OLD'!$M7)*18%+'Data-OLD'!$N7*12% -> 5601.42 | P7: ='Data-OLD'!$K7+'Data-OLD'!$L7+'Data-OLD'!$M7+'Data-OLD'!$N7+'Data-OLD'!$O7 -> 51370.42
A8: 7 | B8: GJ-18-AU-8480 | C8: 1000000 | D8: 80000 | E8: ='Data-OLD'!$C8+'Data-OLD'!$D8 -> 1080000 | F8: 2390 | G8: 0 | H8: 0 | I8: 0 | J8: 0 | K8: =SUM('Data-OLD'!$F8:$J8) -> 2390 | L8: 75 | M8: 75 | N8: 43950 | O8: =SUM('Data-OLD'!$K8+'Data-OLD'!$L8+'Data-OLD'!$M8)*18%+'Data-OLD'!$N8*12% -> 5731.2 | P8: ='Data-OLD'!$K8+'Data-OLD'!$L8+'Data-OLD'!$M8+'Data-OLD'!$N8+'Data-OLD'!$O8 -> 52221.2
A9: 8 | B9: GJ-18-BW-6133 | C9: 1500000 | D9: 0 | E9: ='Data-OLD'!$C9+'Data-OLD'!$D9 -> 1500000 | F9: =8117 -> 8117 | G9: 0 | H9: 0 | I9: 0 | J9: 0 | K9: =SUM('Data-OLD'!$F9:$J9) -> 8117 | L9: 275 | M9: 150 | N9: 44242 | O9: =SUM('Data-OLD'!$K9+'Data-OLD'!$L9+'Data-OLD'!$M9)*18%+'Data-OLD'!$N9*12% -> 6846.6 | P9: ='Data-OLD'!$K9+'Data-OLD'!$L9+'Data-OLD'!$M9+'Data-OLD'!$N9+'Data-OLD'!$O9 -> 59630.6
A10: 9 | B10: GJ-12-BX-8779 | C10: 1600000 | D10: 0 | E10: ='Data-OLD'!$C10+'Data-OLD'!$D10 -> 1600000 | F10: 3804 | G10: 571 | H10: 0 | I10: 0 | J10: -875 | K10: =SUM('Data-OLD'!$F10:$J10) -> 3500 | L10: 375 | M10: 100 | N10: 44242 | O10: =SUM('Data-OLD'!$K10+'Data-OLD'!$L10+'Data-OLD'!$M10)*18%+'Data-OLD'!$N10*12% -> 6024.54 | P10: ='Data-OLD'!$K10+'Data-OLD'!$L10+'Data-OLD'!$M10+'Data-OLD'!$N10+'Data-OLD'!$O10 -> 54241.54
A11: 10 | B11: RJ-32-GB-5192 | C11: 1350000 | D11: 0 | E11: ='Data-OLD'!$C11+'Data-OLD'!$D11 -> 1350000 | F11: 8232 | G11: 0 | H11: 0 | I11: 0 | J11: 0 | K11: =SUM('Data-OLD'!$F11:$J11) -> 8232 | L11: 275 | M11: 150 | N11: 44242 | O11: =SUM('Data-OLD'!$K11+'Data-OLD'!$L11+'Data-OLD'!$M11)*18%+'Data-OLD'!$N11*12% -> 6867.3 | P11: ='Data-OLD'!$K11+'Data-OLD'!$L11+'Data-OLD'!$M11+'Data-OLD'!$N11+'Data-OLD'!$O11 -> 59766.3
A12: 11 | B12: GJ-16-AU-5412 | C12: 1212502 | D12: 0 | E12: ='Data-OLD'!$C12+'Data-OLD'!$D12 -> 1212502 | F12: 17900 | G12: 0 | H12: 0 | I12: 0 | J12: 0 | K12: =SUM('Data-OLD'!$F12:$J12) -> 17900 | L12: 315 | M12: 150 | N12: 43950 | O12: =SUM('Data-OLD'!$K12+'Data-OLD'!$L12+'Data-OLD'!$M12)*18%+'Data-OLD'!$N12*12% -> 8579.7 | P12: ='Data-OLD'!$K12+'Data-OLD'!$L12+'Data-OLD'!$M12+'Data-OLD'!$N12+'Data-OLD'!$O12 -> 70894.7
A13: 12 | B13: GJ-18-AV-4737 | C13: 450000 | D13: 0 | E13: ='Data-OLD'!$C13+'Data-OLD'!$D13 -> 450000 | F13: 722 | G13: 0 | H13: 0 | I13: 0 | J13: 0 | K13: =SUM('Data-OLD'!$F13:$J13) -> 722 | L13: 75 | M13: 75 | N13: 43950 | O13: =SUM('Data-OLD'!$K13+'Data-OLD'!$L13+'Data-OLD'!$M13)*18%+'Data-OLD'!$N13*12% -> 5430.96 | P13: ='Data-OLD'!$K13+'Data-OLD'!$L13+'Data-OLD'!$M13+'Data-OLD'!$N13+'Data-OLD'!$O13 -> 50252.96
A14: 13 | B14: GJ-12-Z-1317 | C14: 530000 | D14: 0 | E14: ='Data-OLD'!$C14+'Data-OLD'!$D14 -> 530000 | F14: 1077 | G14: 0 | H14: 0 | I14: 0 | J14: 0 | K14: =SUM('Data-OLD'!$F14:$J14) -> 1077 | L14: 75 | M14: 75 | N14: 43950 | O14: =SUM('Data-OLD'!$K14+'Data-OLD'!$L14+'Data-OLD'!$M14)*18%+'Data-OLD'!$N14*12% -> 5494.86 | P14: ='Data-OLD'!$K14+'Data-OLD'!$L14+'Data-OLD'!$M14+'Data-OLD'!$N14+'Data-OLD'!$O14 -> 50671.86
A15: 14 | B15: GJ-18-AZ-5588 | C15: 1300000 | D15: 1100000 | E15: ='Data-OLD'!$C15+'Data-OLD'!$D15 -> 2400000 | F15: 4293 | G15: 0 | H15: 0 | I15: 60 | J15: 0 | K15: =SUM('Data-OLD'!$F15:$J15) -> 4353 | L15: 75 | M15: 75 | N15: 43950 | O15: =SUM('Data-OLD'!$K15+'Data-OLD'!$L15+'Data-OLD'!$M15)*18%+'Data-OLD'!$N15*12% -> 6084.54 | P15: ='Data-OLD'!$K15+'Data-OLD'!$L15+'Data-OLD'!$M15+'Data-OLD'!$N15+'Data-OLD'!$O15 -> 54537.54
A16: 15 | B16: GJ-12-Z-2989 | C16: 487000 | D16: 0 | E16: ='Data-OLD'!$C16+'Data-OLD'!$D16 -> 487000 | F16: 1495 | G16: 0 | H16: 0 | I16: 0 | J16: 0 | K16: =SUM('Data-OLD'!$F16:$J16) -> 1495 | L16: 75 | M16: 75 | N16: 43950 | O16: =SUM('Data-OLD'!$K16+'Data-OLD'!$L16+'Data-OLD'!$M16)*18%+'Data-OLD'!$N16*12% -> 5570.1 | P16: ='Data-OLD'!$K16+'Data-OLD'!$L16+'Data-OLD'!$M16+'Data-OLD'!$N16+'Data-OLD'!$O16 -> 51165.1
A17: 16 | B17: GJ-18-AZ-0849 | C17: 1440000 | D17: 0 | E17: ='Data-OLD'!$C17+'Data-OLD'!$D17 -> 1440000 | F17: =2635+3600 -> 6235 | G17: 507 | H17: 0 | I17: 743 | J17: -971 | K17: =SUM('Data-OLD'!$F17:$J17) -> 6514 | L17: 120 | M17: 100 | N17: 43950 | O17: =SUM('Data-OLD'!$K17+'Data-OLD'!$L17+'Data-OLD'!$M17)*18%+'Data-OLD'!$N17*12% -> 6486.12 | P17: ='Data-OLD'!$K17+'Data-OLD'!$L17+'Data-OLD'!$M17+'Data-OLD'!$N17+'Data-OLD'!$O17 -> 57170.12
A18: 17 | B18: GJ-12-Z-1089 | C18: 440000 | D18: 0 | E18: ='Data-OLD'!$C18+'Data-OLD'!$D18 -> 440000 | F18: 1328 | G18: 0 | H18: 0 | I18: 0 | J18: 0 | K18: =SUM('Data-OLD'!$F18:$J18) -> 1328 | L18: 75 | M18: 75 | N18: 43950 | O18: =SUM('Data-OLD'!$K18+'Data-OLD'!$L18+'Data-OLD'!$M18)*18%+'Data-OLD'!$N18*12% -> 5540.04 | P18: ='Data-OLD'!$K18+'Data-OLD'!$L18+'Data-OLD'!$M18+'Data-OLD'!$N18+'Data-OLD'!$O18 -> 50968.04
A19: 18 | B19: GJ-18-AZ-4229 | C19: 900000 | D19: 0 | E19: ='Data-OLD'!$C19+'Data-OLD'!$D19 -> 900000 | F19: 1467 | G19: 0 | H19: 0 | I19: 0 | J19: 0 | K19: =SUM('Data-OLD'!$F19:$J19) -> 1467 | L19: 50 | M19: 0 | N19: 44242 | O19: =SUM('Data-OLD'!$K19+'Data-OLD'!$L19+'Data-OLD'!$M19)*18%+'Data-OLD'!$N19*12% -> 5582.1 | P19: ='Data-OLD'!$K19+'Data-OLD'!$L19+'Data-OLD'!$M19+'Data-OLD'!$N19+'Data-OLD'!$O19 -> 51341.1
A20: 19 | B20: GJ-12-Z-1090 | C20: 455000 | D20: 0 | E20: ='Data-OLD'!$C20+'Data-OLD'!$D20 -> 455000 | F20: 1802 | G20: 0 | H20: 0 | I20: 0 | J20: -631 | K20: =SUM('Data-OLD'!$F20:$J20) -> 1171 | L20: 50 | M20: 50 | N20: 43950 | O20: =SUM('Data-OLD'!$K20+'Data-OLD'!$L20+'Data-OLD'!$M20)*18%+'Data-OLD'!$N20*12% -> 5502.78 | P20: ='Data-OLD'!$K20+'Data-OLD'!$L20+'Data-OLD'!$M20+'Data-OLD'!$N20+'Data-OLD'!$O20 -> 50723.78
A21: 20 | B21: GJ-18-AV-4735 | C21: 481000 | D21: 0 | E21: ='Data-OLD'!$C21+'Data-OLD'!$D21 -> 481000 | F21: 2249 | G21: 0 | H21: 0 | I21: 0 | J21: -1124 | K21: =SUM('Data-OLD'!$F21:$J21) -> 1125 | L21: 275 | M21: 275 | N21: 43950 | O21: =SUM('Data-OLD'!$K21+'Data-OLD'!$L21+'Data-OLD'!$M21)*18%+'Data-OLD'!$N21*12% -> 5575.5 | P21: ='Data-OLD'!$K21+'Data-OLD'!$L21+'Data-OLD'!$M21+'Data-OLD'!$N21+'Data-OLD'!$O21 -> 51200.5
A22: 21 | B22: GJ-09-Z-4266 | C22: 1200000 | D22: 0 | E22: ='Data-OLD'!$C22+'Data-OLD'!$D22 -> 1200000 | F22: 2411 | G22: 0 | H22: 0 | I22: 0 | J22: 0 | K22: =SUM('Data-OLD'!$F22:$J22) -> 2411 | L22: 75 | M22: 75 | N22: 43950 | O22: =SUM('Data-OLD'!$K22+'Data-OLD'!$L22+'Data-OLD'!$M22)*18%+'Data-OLD'!$N22*12% -> 5734.98 | P22: ='Data-OLD'!$K22+'Data-OLD'!$L22+'Data-OLD'!$M22+'Data-OLD'!$N22+'Data-OLD'!$O22 -> 52245.98
A23: 22 | B23: GJ-12-BT-7142 | C23: 2089500 | D23: 0 | E23: ='Data-OLD'!$C23+'Data-OLD'!$D23 -> 2089500 | F23: 8091 | G23: 0 | H23: 0 | I23: 0 | J23: 0 | K23: =SUM('Data-OLD'!$F23:$J23) -> 8091 | L23: 50 | M23: 50 | N23: 44242 | O23: =SUM('Data-OLD'!$K23+'Data-OLD'!$L23+'Data-OLD'!$M23)*18%+'Data-OLD'!$N23*12% -> 6783.42 | P23: ='Data-OLD'!$K23+'Data-OLD'!$L23+'Data-OLD'!$M23+'Data-OLD'!$N23+'Data-OLD'!$O23 -> 59216.42
A24: 23 | B24: GJ-18-BV-9156 | C24: 1080257 | D24: 0 | E24: ='Data-OLD'!$C24+'Data-OLD'!$D24 -> 1080257 | F24: 1977 | G24: 408 | H24: 0 | I24: 743 | J24: -625 | K24: =SUM('Data-OLD'!$F24:$J24) -> 2503 | L24: 50 | M24: 50 | N24: 43950 | O24: =SUM('Data-OLD'!$K24+'Data-OLD'!$L24+'Data-OLD'!$M24)*18%+'Data-OLD'!$N24*12% -> 5742.54 | P24: ='Data-OLD'!$K24+'Data-OLD'!$L24+'Data-OLD'!$M24+'Data-OLD'!$N24+'Data-OLD'!$O24 -> 52295.54
A25: 24 | B25: GJ-18-BV-8816 | C25: 1500000 | D25: 0 | E25: ='Data-OLD'!$C25+'Data-OLD'!$D25 -> 1500000 | F25: 4197 | G25: 0 | H25: 0 | I25: 0 | J25: 0 | K25: =SUM('Data-OLD'!$F25:$J25) -> 4197 | L25: 110 | M25: 110 | N25: 44242 | O25: =SUM('Data-OLD'!$K25+'Data-OLD'!$L25+'Data-OLD'!$M25)*18%+'Data-OLD'!$N25*12% -> 6104.1 | P25: ='Data-OLD'!$K25+'Data-OLD'!$L25+'Data-OLD'!$M25+'Data-OLD'!$N25+'Data-OLD'!$O25 -> 54763.1
A26: 25 | B26: GJ-18-AV-7468 | C26: 1100000 | D26: 0 | E26: ='Data-OLD'!$C26+'Data-OLD'!$D26 -> 1100000 | F26: 1678 | G26: 0 | H26: 0 | I26: 0 | J26: 0 | K26: =SUM('Data-OLD'!$F26:$J26) -> 1678 | L26: 110 | M26: 110 | N26: 44242 | O26: =SUM('Data-OLD'!$K26+'Data-OLD'!$L26+'Data-OLD'!$M26)*18%+'Data-OLD'!$N26*12% -> 5650.68 | P26: ='Data-OLD'!$K26+'Data-OLD'!$L26+'Data-OLD'!$M26+'Data-OLD'!$N26+'Data-OLD'!$O26 -> 51790.68
A27: 26 | B27: GJ-18-AX-6955 | C27: 1100000 | D27: 0 | E27: ='Data-OLD'!$C27+'Data-OLD'!$D27 -> 1100000 | F27: 2377 | G27: 0 | H27: 0 | I27: 0 | J27: 0 | K27: =SUM('Data-OLD'!$F27:$J27) -> 2377 | L27: 50 | M27: 50 | N27: 43950 | O27: =SUM('Data-OLD'!$K27+'Data-OLD'!$L27+'Data-OLD'!$M27)*18%+'Data-OLD'!$N27*12% -> 5719.86 | P27: ='Data-OLD'!$K27+'Data-OLD'!$L27+'Data-OLD'!$M27+'Data-OLD'!$N27+'Data-OLD'!$O27 -> 52146.86
A28: 27 | C28: 0 | D28: 0 | E28: ='Data-OLD'!$C28+'Data-OLD'!$D28 -> 0 | F28: 0 | G28: 0 | H28: 0 | I28: 0 | J28: 0 | K28: =SUM('Data-OLD'!$F28:$J28) -> 0 | L28: 0 | M28: 0 | N28: 0 | O28: =SUM('Data-OLD'!$K28+'Data-OLD'!$L28+'Data-OLD'!$M28)*18%+'Data-OLD'!$N28*12% -> 0 | P28: ='Data-OLD'!$K28+'Data-OLD'!$L28+'Data-OLD'!$M28+'Data-OLD'!$N28+'Data-OLD'!$O28 -> 0
